Workbook
Name _p7_2025: '[1]7mo25'!$A$1:$H$137
Name _p8_2025: '[1]8vo25'!$A$1:$H$143

Sheet Hoja1
A1: CONTRATO DE APRENDIZAJE | H1: COORDINACIÓN VIRTUAL
A2: FECHA DE GESTIÓN | B2: FICHA | C2: TIPO DE DOCUMENTO | D2: NUMERO DE DOCUMENTO | E2: NOMBRE | F2: PROGRAMA | H2: VERIFICACIÓN COORDINACION VIRTUAL | I2: FECHA DE VERIFICACIÓN | J2: NOMBRE DE LA PERSONA | K2: CONFIRMACIÓN DE ENVÍO DE LA CARTA DE FECHAS SI / NO
A3: 46044 | B3: 3235891 | C3: CEDULA DE CIUDADANIA | D3: 1007409733 | E3: MONICA YULITZA REYES ROJAS | F3: TECNÓLOGO EN ANALISIS Y DESARROLLO DE SOFTWARE. | H3: FALTA 47 JUCIOS POR EVALUAR | I3: 22/01/2026 | J3: KARINA ROJAS
A4: 46044 | B4: 2977755 | C4: CEDULA DE CIUDADANIA | D4: 1044616637 | E4: CRISTIAN MARCOS PEREZ | F4: TECNÓLOGO EN COORDINACION DE PROCESOS LOGISTICOS | H4: FALTA 48 JUICIOS POR EVALUAR | I4: 22/01/2026 | J4: KARINA ROJAS
A5: 46044 | B5: 3336173 | C5: CEDULA DE CIUDADANIA | D5: 1002609671 | E5: VALENTINA ARIAS ARISTIZABAL | F5: TECNÓLOGO EN ANALISIS Y DESARROLLO DE SOFTWARE. | H5: FALTA 66 JUICIOS POR EVALUAR | I5: 22/01/2026 | J5: KARINA ROJAS
A6: 46044 | B6: 3186282 | C6: CEDULA DE CIUDADANIA | D6: 1235538925 | E6: OSNEIDY DEL PILAR ROLON COTES | F6: TÉCNICO EN SERVICIOS COMERCIALES Y FINANCIEROS | H6: ESTA AL DIA | I6: 22/01/2026 | J6: KARINA ROJAS
A7: 46044 | B7: 3186283 | C7: CEDULA DE CIUDADANIA | D7: 1045739357 | E7: VERONICA DEL CARMEN CALDERON OCHOA | F7: TÉCNICO EN SERVICIOS COMERCIALES Y FINANCIEROS | H7: ESTA AL DIA | I7: 22/01/2026 | J7: KARINA ROJAS
A8: 46044 | B8: 3236062 | C8: CEDULA DE CIUDADANIA | D8: 1089481201 | E8: TATIANA SALOME BOLAÑOS YANDUN | F8: TÉCNICO EN SERVICIOS COMERCIALES Y FINANCIEROS | H8: FALTA 8 JUICIOS POR EVALUAR | I8: 22/01/2026 | J8: KARINA ROJAS
A9: 46044 | B9: 3186284 | C9: CEDULA DE CIUDADANIA | D9: 1034656784 | E9: ANDRES GEOVANNY SENEJOA CARRILLO | F9: TÉCNICO EN SERVICIOS COMERCIALES Y FINANCIEROS | H9: FALTA 3 JUICIOS POR EVALUAR | I9: 22/01/2026 | J9: KARINA ROJAS
A10: 46044 | B10: 2879838 | C10: CEDULA DE CIUDADANIA | D10: 1007255079 | E10: STEPHANY MARTINEZ ALANDETE | F10: TECNÓLOGO EN COORDINACION DE PROCESOS LOGISTICOS | H10: ESTA AL DIA | I10: 22/01/2026 | J10: KARINA ROJAS
A11: 46044 | B11: 3186222 | C11: CEDULA DE CIUDADANIA | D11: 1002201083 | E11: SHIRLI YASMIN PUERTA FLOREZ | F11: TÉCNICO EN OPERACIONES DE COMERCIO EXTERIOR | H11: ESTA AL DIA | I11: 22/01/2026 | J11: KARINA ROJAS
A12: 46044 | B12: 3335836 | C12: CEDULA DE CIUDADANIA | D12: 1069402661 | E12: YESMI PAOLA AMAYA RODRIGUEZ | F12: TECNOLOGO GESTION CONTABLE Y DE INFORMACION FINANCIERA | H12: FALTA 65 JUICIOS POR EVALUAR | I12: 22/01/2026 | J12: KARINA ROJAS
A13: 46044 | B13: 3186304 | C13: CEDULA DE CIUDADANIA | D13: 1073176065 | E13: YULIHET KATERINE ESPINOSA GOMEZ | F13: TÉCNICO EN SERVICIOS Y OPERACIONES MICROFINANCIERAS | H13: ESTA AL DIA | I13: 22/01/2026 | J13: KARINA ROJAS
A14: 46044 | B14: 2977227 | C14: CEDULA DE CIUDADANIA | D14: 1034986359 | E14: SOFIA AGUDELO HERNANDEZ | F14: TECNÓLOGO EN DESARROLLO DE MEDIOS GRAFICOS VISUALES | H14: FALTA 6 JUICIOS POR EVALUAR | I14: 22/01/2026 | J14: KARINA ROJAS
... A31: 46044 | B31: 2879843 | C31: CEDULA DE CIUDADANIA | D31: 52982445 | E31: LETTY ANDREA ALONSO MELO | F31: TECNÓLOGO EN COORDINACION DE PROCESOS LOGISTICOS | H31: ESTA AL DIA | I31: 26/01/2026 | J31: KARINA ROJAS
A32: 26/01/2026 | B32: 3335839 | C32: CEDULA DE CIUDADANIA | D32: 1082774480 | E32: GILMA DORADO SALAMANCA | F32: TECNOLOGO GESTION CONTABLE Y DE INFORMACION FINANCIERA | H32: FALTAN 67 JUICIOS POR EVALUAR | I32: 26/01/2026 | J32: KARINA ROJAS
A33: 26/01/2026 | B33: 3186304 | C33: CEDULA DE CIUDADANIA | D33: 1073519402 | E33: LISETH JOHANA ZAMBRANO MAHECHA | F33: TÉCNICO EN SERVICIOS Y OPERACIONES MICROFINANCIERAS | H33: ESTA AL DIA | I33: 26/01/2026 | J33: KARINA ROJAS
A34: 26/01/2026 | B34: 3186285 | C34: CEDULA DE CIUDADANIA | D34: 40942411 | E34: YURANCEY BOLAÑO GARAY | F34: TÉCNICO EN SERVICIOS COMERCIALES Y FINANCIEROS | H34: ESTA AL DIA | I34: 26/01/2026 | J34: KARINA ROJAS
A35: 26/01/2026 | B35: 3186282 | C35: CEDULA DE CIUDADANIA | D35: 1101818015 | E35: LESLI JOHANA GONZALEZ MONTES | F35: TÉCNICO EN SERVICIOS COMERCIALES Y FINANCIEROS | H35: FALTA 6 JUICIOS POR EVALUAR | I35: 26/01/2026 | J35: KARINA ROJAS
A36: 26/01/2026 | B36: 3186282 | C36: CEDULA DE CIUDADANIA | D36: 1225092989 | E36: ELIZABETH CAMPO QUIJANO | F36: TÉCNICO EN SERVICIOS COMERCIALES Y FINANCIEROS | H36: ESTA AL DIA | I36: 26/01/2026 | J36: KARINA ROJAS
A37: 28/01/2026 | B37: 3186284 | C37: CEDULA DE CIUDADANIA | D37: 1075682995 | E37: CRISTIAN CAMILO TORRES BELTRAN | F37: TÉCNICO EN SERVICIOS COMERCIALES Y FINANCIEROS
A38: 28/01/2026 | B38: 2977137 | C38: CEDULA DE CIUDADANIA | D38: 1042767503 | E38: SERGIO ANDRES AGUDELO PEREZ | F38: TECNÓLOGO EN DESARROLLO MULTIMEDIA Y WEB

Sheet Hoja2
B6: D. | C6: No. Documento | D6: Nombres y Apellidos | E6: Ficha | F6: Fecha Inicio | G6: Fecha Final | H6: Nivel Formación | I6: Modalidad | J6: Programa | K6: Estado | L6: Trimestre | M6: Intensidad Horaria
K7: (si esta activa) | L7: (en que va)
B8: C.C | C8: 1001187205 | D8: LEIDY JOHANA CAVIEDES ORDUZ | E8: 3118513 | F8: 45614 | G8: 46435 | H8: TECNÓLOGO | I8: VIRTUAL | J8: DESARROLLO DE MEDIOS GRAFICOS VISUALES | K8: FORMACION | L8: 6 TRIMESTRE | M8: 34 Horas

Sheet Consultar
C6: FICHA | D6: 3070336
C9: FECHA INICIO | D9: =VLOOKUP(D6,'PE04'!$A$2:$G$353,4,FALSE) -> 16/09/2024
C10: FECHA FIN LECTIVA | D10: =VLOOKUP(D6,'PE04'!$A$2:$G$353,5,FALSE) -> 46188
C11: FECHA FIN | D11: =VLOOKUP(D6,'PE04'!$A$2:$G$353,6,FALSE) -> 15/12/2026
C12: ESTADO | D12: =VLOOKUP(D6,'PE04'!$A$2:$G$353,7,FALSE) -> En ejecucion
C13: NIVEL | D13: =VLOOKUP(D6,'PE04'!$A$2:$G$353,2,FALSE) -> TECNÓLOGO
C14: PROGRAMA | D14: =VLOOKUP(D6,'PE04'!$A$2:$G$353,3,FALSE) -> COORDINACION DE PROCESOS LOGISTICOS
C15: TRIMESTRE | D15: ="Trimestre " & MIN(8, INT(DATEDIF(D9, MIN(D11, TODAY()), "m") / 3) + 1) -> Trimestre 7
C16: ACUERDO | D16: =IF(VALUE(D9) < DATE(2024, 11, 20), "ACUERDO 007", "ACUERDO 009") -> ACUERDO 007
C17: FASE | D17: {=_xlfn.IFS( DATEDIF(D9, TODAY(), "m") < 1, "INDUCCION", DATEDIF(D9, TODAY(), "m") <= 4, "ANALISIS", DATEDIF(D9, TODAY(), "m") <= 9, "PLANEACION", DATEDIF(D9, TODAY(), "m") <= 13, "EJECUCION", DATEDIF(D9, TODAY(), "m") <= 18, "EVALUACION", TRUE, "NO ESTA EN LECTIVA" )} -> EVALUACION
C19: INSTRUCTOR TECNICO 2026 | D19: =VLOOKUP(D6,Hoja7!$1:$1048576,16,FALSE) -> MARIA PAOLA GIRALDO HERRERA
C21: INSTRUCTOR TECNICO 2025 | D21: =VLOOKUP(D6,Hoja7!$1:$1048576,13,FALSE) -> OSCAR EDUARDO SARMIENTO SAAVEDRA
C24: TRANSVERSALES VISTAS | D24: {=_xlfn.LET( _xlpm.datos, TRANSPOSE(_xlfn.XLOOKUP(D6,Hoja7!$A:$A,Hoja7!$S:$BO,"NO SE HA PROGRAMADO O ES ANTERIOR A LA BASE",0)), _xlfn._xlws.FILTER(_xlpm.datos, (_xlpm.datos<>"")*(_xlpm.datos<>0), "Sin datos programados") )} -> COM | F24: TRANSVERSALES FALTANTES | G24: {=TRANSPOSE(_xlfn.XLOOKUP(D6,Hoja7!A:A,Hoja7!BS:BS,"NO TIENE PENDIENTES",0))}
D25: JORGE ARMANDO PIEDRAHITA CABRERA
D26: MAT
D27: ELKIN DURAN MANCIPE
D28: CIE
D29: LAURA SOFIA PAEZ GALLO
D30: TIC
D31: ERICK RUIZ NOREÑA
D32: INV
D33: FRANCI PAOLA LOZANO PIRAQUIVE
D34: DER
D35: HECTOR ANDRES CIPAMOCHA CENTENO
D36: ETI
... D44: DAVID BAUTISTA ROMERO

Sheet Hoja6
A1: PROGRAMA | B1: NIVEL | C1: COD PRO | D1: VER | E1: INDUCCION | F1: ANALISIS | I1: PLANEACION | N1: EJECUCION | R1: EVALUACION | W1: NEW
A2: ASESORIA COMERCIAL | B2: TÉCNICO | C2: 631101 | D2: 2 | F2: TIC | G2: MAT | H2: CIE | I2: CUL | J2: ETI | K2: COM | N2: SST | O2: EMP | R2: DER | V2: =COUNTIF(F2:U2,"*") -> 9 | W2: TIC MAT EMP CIE CUL ETI COM SST DER
A3: CONTABILIZACION DE OPERACIONES COMERCIALES Y FINANCIERAS | B3: TÉCNICO | C3: 133100 | D3: 2 | F3: EMP | G3: TIC | H3: MAT | J3: COM | K3: ETI | N3: DER | O3: SST | R3: CUL | V3: =COUNTIF(F3:U3,"*") -> 8 | W3: EMP TIC MAT COM ETI DER SST CUL
A4: OPERACIONES DE COMERCIO EXTERIOR | B4: TÉCNICO | F4: MAT | G4: TIC | H4: COM | I4: CUL | J4: ETI | K4: SST | N4: EMP | R4: DER | V4: =COUNTIF(F4:U4,"*") -> 8 | W4: MAT TIC COM CUL ETI SST EMP DER
A5: OPERACIONES COMERCIALES EN RETAIL | B5: TÉCNICO | F5: TIC | G5: MAT | H5: FIS | I5: CUL | J5: ETI | K5: COM | N5: SST | O5: DER | R5: EMP | V5: =COUNTIF(F5:U5,"*") -> 9 | W5: TIC MAT FIS CUL ETI COM SST DER EMP
A6: SERVICIOS COMERCIALES Y FINANCIEROS | B6: TÉCNICO | C6: 133303 | D6: 1 | F6: TIC | G6: MAT | H6: COM | J6: CUL | N6: SST | O6: EMP | P6: ETI | R6: DER | V6: =COUNTIF(F6:U6,"*") -> 8 | W6: TIC MAT COM CUL SST EMP ETI DER
A7: SERVICIOS Y OPERACIONES MICROFINANCIERAS | B7: TÉCNICO | F7: MAT | G7: SST | H7: COM | I7: ETI | J7: CUL | K7: DER | N7: TIC | R7: EMP | V7: =COUNTIF(F7:U7,"*") -> 8 | W7: MAT SST COM ETI CUL DER TIC EMP
A8: ANALISIS Y DESARROLLO DE SOFTWARE | B8: TECNÓLOGO | C8: 228118 | D8: 1 | F8: MAT | G8: TIC | J8: COM | K8: INV | L8: FIS | N8: EMP | O8: ETI | P8: SST | Q8: CUL | R8: DER | V8: =COUNTIF(F8:U8,"*") -> 10 | W8: MAT TIC COM INV FIS EMP ETI SST CUL DER
A9: ANIMACION 3D | B9: TECNÓLOGO | C9: 524703 | D9: 1 | F9: MAT | G9: CIE | H9: COM | I9: TIC | J9: CUL | K9: SST | N9: INV | O9: ETI | R9: EMP | S9: DER | V9: =COUNTIF(F9:U9,"*") -> 10 | W9: MAT CIE COM TIC CUL SST INV ETI EMP DER
A10: ANIMACION DIGITAL | B10: TECNÓLOGO | C10: 513601 | D10: 3 | F10: TIC | G10: COM | H10: MAT | I10: CIE | J10: INV | N10: ETI | O10: SST | P10: CUL | R10: EMP | S10: DER | V10: =COUNTIF(F10:U10,"*") -> 10 | W10: TIC COM MAT CIE INV ETI SST CUL EMP DER
A11: COORDINACION DE PROCESOS LOGISTICOS | B11: TECNÓLOGO | C11: 121523 | D11: 2 | E11: IND | F11: INV | G11: COM | H11: TIC | J11: MAT | K11: CIE | L11: DER | N11: ETI | O11: SST | R11: EMP | S11: CUL | V11: =COUNTIF(F11:U11,"*") -> 10 | W11: INV COM TIC MAT CIE DER ETI SST EMP CUL
A12: DESARROLLO DE MEDIOS GRAFICOS VISUALES | B12: TECNÓLOGO | C12: 522309 | D12: 1 | F12: TIC | G12: MAT | H12: COM | I12: SST | J12: EMP | K12: DER | N12: INV | O12: FIS | P12: CUL | R12: ETI | V12: =COUNTIF(F12:U12,"*") -> 10 | W12: TIC MAT COM SST EMP DER INV FIS CUL ETI
A13: DESARROLLO MULTIMEDIA Y WEB | B13: TECNÓLOGO | C13: 217320 | D13: 1 | F13: MAT | G13: COM | H13: TIC | I13: INV | J13: FIS | K13: CUL | L13: ETI | N13: SST | R13: EMP | S13: DER | V13: =COUNTIF(F13:U13,"*") -> 10 | W13: MAT COM TIC INV FIS CUL ETI SST EMP DER
A14: DESARROLLO PUBLICITARIO | B14: TECNÓLOGO | C14: 124100 | D14: 1 | F14: TIC | G14: ETI | I14: COM | J14: EMP | K14: INV | N14: MAT | O14: SST | R14: CUL | S14: CIE | T14: DER | V14: =COUNTIF(F14:U14,"*") -> 10 | W14: TIC ETI COM EMP INV MAT SST CUL CIE DER
A15: GESTION CONTABLE Y DE INFORMACION FINANCIERA | B15: TECNÓLOGO | C15: 123101 | D15: 1 | F15: TIC | G15: COM | H15: MAT | I15: ETI | J15: DER | N15: CUL | O15: EMP | P15: INV | R15: SST | V15: =COUNTIF(F15:U15,"*") -> 9 | W15: TIC COM MAT ETI DER CUL EMP INV SST
A21: ALBERTO ANTONIO TAPIA TORRES
A22: ALEX EDUARDO ZAMBRANO PEREZ
A23: ANA MILENA MOSQUERA SEVILLA
A24: ANDRES RUBIANO CUCARIAN
A25: ANGELICA JANETH RODRIGUEZ ALONSO
A26: CAMILO ERNESTO PARRA LOPEZ
A27: CARLOS HERNANDEZ ARCILA
A28: CESAR AUGUSTO BERMEO
A29: CESAR AUGUSTO HERNANDEZ RODRIGUEZ
A30: CHRISTIAN CAMILO RODRIGUEZ SALAS
A31: CINDY YOHANA BOHORQUEZ GARZON
A32: CLAUDIA ROCIO VACCA GARCIA
... A115: EDICSON NIÑO AREVALO

Sheet Hoja7
A1: 1 | B1: 2 | D1: 4 | E1: 5 | F1: 6 | G1: 7 | H1: 8 | I1: 9 | J1: 10 | K1: 11 | L1: 12 | M1: 13 | N1: 14 | O1: 15 | Q1: 16 | R1: 17 | S1: 18 | T1: 19 | U1: 20 | V1: 21 | W1: 22 | X1: 23 | Y1: 24 | Z1: 25 | AA1: 26 | AB1: 27 | AC1: 28 | AD1: 29 | AE1: 30 | AF1: 31 | AG1: 32 | AH1: 33 | AI1: 34 | AJ1: 35 | AK1: 36 | AL1: 37 | AM1: 38 | AN1: 39 | AO1: 40 | AP1: 41 | AQ1: 42 | AR1: 43 | AS1: 44 | AT1: 45 | AU1: 46 | AV1: 47 | AW1: 48 | AX1: 49 | AY1: 50 | AZ1: 51 | BA1: 52 | BB1: 53 | BC1: 54 | BD1: 55 | BP1: 56 | BU1: 57 | BV1: 58
A2: FICHA | B2: NIVEL | C2: APRENDICES | D2: PROGRAMA | E2: F_INI | F2: F_FIN_ LEC | G2: F_FIN | H2: INSTRUCTOR_TECNICO 2024 | I2: INSTRUCTOR_TECNICO_ANT 2024 | J2: INSTRUCTOR BIENVENIDA 2024 | K2: INSTRUCTOR INDUCCION 2025 | L2: INSTRUCTOR_TECNICO_ANT 2025 | M2: INSTRUCTOR TECNICO 2025 | N2: INSTRUCTOR_BILINGUISMO 2024/2025 | O2: INSTRUCTOR BILINGUIMOS 2025 | P2: INSTRUCTOR TECNICO 2026 | Q2: TODAS | R2: FALTAN EN 2024 | S2: Transversal 5to periodo | T2: Instructor 5to periodo | U2: Transversal 6to periodo | V2: Instructor 6to periodo | W2: Transversal 7mo periodo | X2: Instructor 7mo periodo | Y2: Transversal 8vo periodo | Z2: Instructor 8vo periodo | AA2: Transversal 9no Periodo | AB2: Instructor 9no periodo | AC2: Transvesal 1er Periodo 2025 | AD2: Instructor 1er Periodo 2025 | AE2: Transversal 2do periodo 2025 | AF2: Instructor 2do periodo 2025 | AG2: Transversal 3er periodo 2025 - A | AH2: Instructor 3er periodo 2025 -A | AI2: Transversal 3er periodo 2025 - B | AJ2: Instructor 3er periodo 2025 - B | AK2: Transvesal 4to periodo 2025 - A | AL2: Instructor 4to periodo 2025 -A | AM2: Transversal 4to periodo 2025 - B | AN2: Instructor 4to periodo 2025 - B | AO2: Transversal 5to periodo 2025 - A | AP2: Instructor 5to periodo 2025 - A | AQ2: Transversal 5to periodo 2025 - B | AR2: Instructor 5to periodo 2025 -B | AS2: Transversal 6to periodo 2025 - A | AT2: Instructor 6to periodo 2025 - A | AU2: Transversal 6to periodo 2025 - B | AV2: Instructor 6to periodo 2025 -B | AW2: Transversal 7mo periodo 2025 - A | AX2: Instructor 7mo periodo 2025 - A | AY2: Transversal 7mo periodo 2025 - B | AZ2: Instructor 7mo periodo 2025 -B | BA2: Transversal 8vo periodo 2025 - A | BB2: Instructor 8vo periodo 2025 - A | BC2: Transversal 8vo periodo 2025 - B | BD2: Instructor 8vo periodo 2025 - B | BE2: Transversal 9vo periodo 2025 - A | BF2: Instructor 9No periodo 2025 - A | BG2: Transversal 9vo periodo 2025 - B | BH2: Instructor 9No periodo 2025 - B | BI2: Transversal 1er periodo 2026 - A | BJ2: Instructor 1er periodo 2026 - A | BK2: Instructor Bilinguismo 1er Periodo | BL2: Transversal 2do periodo 2026 - A | BM2: Instructor 2do periodo 2026 - A | BN2: Transversal 2do periodo 2026 - B | BO2: Instructor 2do periodo 2026 - B | BP2: FALTAN | BQ2: NUEVAS FALTANTES | BR2: NUEVAS FALTANTES1 | BS2: NUEVAS FALTANTES2 | BU2: ACTIVOS Bilinguismo | BV2: Observación
A3: 3186207 | B3: TECNICO | C3: 71 | D3: OPERACIONES COMERCIALES EN RETAIL | E3: 31/03/2025 | F3: 46021 | G3: 30/06/2026 | K3: KEBIN CUESTA RENTERIA | M3: KEBIN CUESTA RENTERIA | O3: JULIAN FERNANDO GARNICA SEPULVEDA | Q3: FIS SST COM DER ETI EMP CUL MAT TIC | AG3: FIS | AH3: CAMILO ERNESTO CALDERON GALINDO | AI3: COM | AJ3: JORGE ARMANDO PIEDRAHITA CABRERA | AK3: TIC | AL3: ERICK RUIZ NOREÑA | AM3: MAT | AN3: JULIANA HERNANDEZ BARRERA | AO3: CUL | AP3: MELISSA ANDREA LAITON GARNICA | AS3: ETI | AT3: OLGA STELLA PARDO SARAY | AU3: SST | AV3: JORGE IVAN PEREZ GAITAN | AW3: DER | AX3: =IFERROR(VLOOKUP(A3,_p7_2025,2,FALSE),"") -> HECTOR ANDRES CIPAMOCHA CENTENO | BA3: EMP | BB3: =VLOOKUP(A3,_p8_2025,2,FALSE) -> ESTEFANIA SANDOVAL CRUZ | BU3: 32 | BV3: actual
A4: 3186220 | B4: TECNICO | C4: 90 | D4: OPERACIONES DE COMERCIO EXTERIOR | E4: 31/03/2025 | F4: 46021 | G4: 30/06/2026 | K4: LUISA ADRIANA CORREDOR GALVIS | M4: DARLING NATHALI GOMEZ OSPINA | O4: JULIAN FERNANDO GARNICA SEPULVEDA | Q4: SST COM DER ETI EMP CUL MAT TIC | AG4: SST | AH4: MARINELLA DIAZ ACOSTA | AI4: COM | AJ4: JORGE ARMANDO PIEDRAHITA CABRERA | AK4: MAT | AL4: WILDER JULIAN ARIAS HERNANDEZ | AM4: TIC | AN4: SONIA PATRICIA CASTAÑEDA CAYCEDO | AO4: CUL | AP4: CHRISTIAN CAMILO RODRIGUEZ SALAS | AS4: ETI | AT4: IVAN DARIO RODRIGUEZ BUSTAMANTE | AW4: EMP | AX4: =IFERROR(VLOOKUP(A4,_p7_2025,2,FALSE),"") -> ESTEFANIA SANDOVAL CRUZ | BA4: DER | BB4: =VLOOKUP(A4,_p8_2025,2,FALSE) -> HECTOR ANDRES CIPAMOCHA CENTENO | BU4: 28 | BV4: actual
A5: 3186221 | B5: TECNICO | C5: 58 | D5: OPERACIONES DE COMERCIO EXTERIOR | E5: 31/03/2025 | F5: 46021 | G5: 30/06/2026 | K5: LUISA ADRIANA CORREDOR GALVIS | M5: DARLING NATHALI GOMEZ OSPINA | O5: JULIAN FERNANDO GARNICA SEPULVEDA | Q5: SST COM DER ETI EMP CUL MAT TIC | AG5: SST | AH5: MARINELLA DIAZ ACOSTA | AI5: COM | AJ5: CESAR AUGUSTO BERMEO | AK5: MAT | AL5: ELKIN DURAN MANCIPE | AM5: TIC | AN5: SONIA PATRICIA CASTAÑEDA CAYCEDO | AO5: CUL | AP5: CHRISTIAN CAMILO RODRIGUEZ SALAS | AS5: ETI | AT5: NELSON ALFREDO VARGAS MORA | AW5: EMP | AX5: =IFERROR(VLOOKUP(A5,_p7_2025,2,FALSE),"") -> ALBERTO ANTONIO TAPIA TORRES | BA5: DER | BB5: =VLOOKUP(A5,_p8_2025,2,FALSE) -> HECTOR ANDRES CIPAMOCHA CENTENO | BU5: 30 | BV5: actual
A6: 3186222 | B6: TECNICO | C6: 64 | D6: OPERACIONES DE COMERCIO EXTERIOR | E6: 31/03/2025 | F6: 46021 | G6: 30/06/2026 | K6: LUISA ADRIANA CORREDOR GALVIS | M6: DARLING NATHALI GOMEZ OSPINA | O6: JULIAN FERNANDO GARNICA SEPULVEDA | Q6: SST COM DER ETI EMP CUL MAT TIC | AG6: SST | AH6: MARINELLA DIAZ ACOSTA | AI6: COM | AJ6: CESAR AUGUSTO BERMEO | AK6: MAT | AL6: ELKIN DURAN MANCIPE | AM6: TIC | AN6: SONIA PATRICIA CASTAÑEDA CAYCEDO | AO6: CUL | AP6: CHRISTIAN CAMILO RODRIGUEZ SALAS | AS6: ETI | AT6: IVAN DARIO RODRIGUEZ BUSTAMANTE | AW6: EMP | AX6: =IFERROR(VLOOKUP(A6,_p7_2025,2,FALSE),"") -> ESTEFANIA SANDOVAL CRUZ | BA6: DER | BB6: =VLOOKUP(A6,_p8_2025,2,FALSE) -> MARIA CAROLINA GOMEZ CALLE | BU6: 35 | BV6: actual
A7: 3186281 | B7: TECNICO | C7: 70 | D7: SERVICIOS COMERCIALES Y FINANCIEROS | E7: 31/03/2025 | F7: 46021 | G7: 30/06/2026 | K7: LAURA CRISTINA RIAÑO ARIZA | M7: LAURA CRISTINA RIAÑO ARIZA | O7: ANGELA JULIETTE SILVA VELANDIA | Q7: TIC MAT COM CUL SST EMP ETI DER | AG7: TIC | AH7: CRISTINA CASTAÑO CASTILLO | AI7: MAT | AJ7: JULIANA HERNANDEZ BARRERA | AK7: ETI | AL7: IVAN DARIO RODRIGUEZ BUSTAMANTE | AM7: CUL | AN7: MELISSA ANDREA LAITON GARNICA | AO7: EMP | AP7: LUIS ARTURO BASTIDAS | AS7: SST | AT7: JORGE IVAN PEREZ GAITAN | AW7: DER | AX7: =IFERROR(VLOOKUP(A7,_p7_2025,2,FALSE),"") -> LAURA STHEPHANIA SANCHEZ PABON | BA7: COM | BB7: =VLOOKUP(A7,_p8_2025,2,FALSE) -> CESAR AUGUSTO BERMEO | BU7: 42 | BV7: actual
A8: 3186282 | B8: TECNICO | C8: 68 | D8: SERVICIOS COMERCIALES Y FINANCIEROS | E8: 31/03/2025 | F8: 46021 | G8: 30/06/2026 | K8: LAURA CRISTINA RIAÑO ARIZA | M8: LAURA CRISTINA RIAÑO ARIZA | O8: ANGELA JULIETTE SILVA VELANDIA | Q8: TIC MAT COM CUL SST EMP ETI DER | AG8: TIC | AH8: CRISTINA CASTAÑO CASTILLO | AI8: MAT | AJ8: JULIANA HERNANDEZ BARRERA | AK8: ETI | AL8: OLGA STELLA PARDO SARAY | AM8: CUL | AN8: MELISSA ANDREA LAITON GARNICA | AO8: EMP | AP8: LUIS ARTURO BASTIDAS | AS8: SST | AT8: DEISY JULIETH GARCIA CASTAÑEDA | AW8: DER | AX8: =IFERROR(VLOOKUP(A8,_p7_2025,2,FALSE),"") -> LAURA STHEPHANIA SANCHEZ PABON | BA8: COM | BB8: =VLOOKUP(A8,_p8_2025,2,FALSE) -> CESAR AUGUSTO BERMEO | BU8: 32 | BV8: actual
A9: 3186283 | B9: TECNICO | C9: 64 | D9: SERVICIOS COMERCIALES Y FINANCIEROS | E9: 31/03/2025 | F9: 46021 | G9: 30/06/2026 | K9: LAURA CRISTINA RIAÑO ARIZA | M9: LAURA CRISTINA RIAÑO ARIZA | O9: ANGELA JULIETTE SILVA VELANDIA | Q9: TIC MAT COM CUL SST EMP ETI DER | AG9: TIC | AH9: CRISTINA CASTAÑO CASTILLO | AI9: MAT | AJ9: JULIANA HERNANDEZ BARRERA | AK9: ETI | AL9: NELSON ALFREDO VARGAS MORA | AM9: CUL | AN9: MELISSA ANDREA LAITON GARNICA | AO9: EMP | AP9: ALBERTO ANTONIO TAPIA TORRES | AS9: SST | AT9: DEISY JULIETH GARCIA CASTAÑEDA | AW9: DER | AX9: =IFERROR(VLOOKUP(A9,_p7_2025,2,FALSE),"") -> MARIA CAROLINA GOMEZ CALLE | BA9: COM | BB9: =VLOOKUP(A9,_p8_2025,2,FALSE) -> JORGE ARMANDO PIEDRAHITA | BU9: 28 | BV9: actual
A10: 3186284 | B10: TECNICO | C10: 70 | D10: SERVICIOS COMERCIALES Y FINANCIEROS | E10: 31/03/2025 | F10: 46021 | G10: 30/06/2026 | K10: MOISES EDGARDO MERIÑO POLO | L10: MOISES EDGARDO MERIÑO POLO | M10: FRANKELI RODRIGUEZ VELASCO | O10: ANGELA JULIETTE SILVA VELANDIA | Q10: TIC MAT COM CUL SST EMP ETI DER | AG10: TIC | AH10: CRISTINA CASTAÑO CASTILLO | AI10: MAT | AJ10: JULIANA HERNANDEZ BARRERA | AK10: ETI | AL10: IVAN DARIO RODRIGUEZ BUSTAMANTE | AM10: CUL | AN10: CHRISTIAN CAMILO RODRIGUEZ SALAS | AO10: EMP | AP10: ALBERTO ANTONIO TAPIA TORRES | AS10: SST | AT10: MARINELLA DIAZ ACOSTA | AW10: DER | AX10: =IFERROR(VLOOKUP(A10,_p7_2025,2,FALSE),"") -> MARIA CAROLINA GOMEZ CALLE | BA10: COM | BB10: =VLOOKUP(A10,_p8_2025,2,FALSE) -> JORGE ARMANDO PIEDRAHITA | BU10: 34 | BV10: actual
A11: 3186285 | B11: TECNICO | C11: 76 | D11: SERVICIOS COMERCIALES Y FINANCIEROS | E11: 31/03/2025 | F11: 46021 | G11: 30/06/2026 | K11: MOISES EDGARDO MERIÑO POLO | L11: MOISES EDGARDO MERIÑO POLO | M11: FRANKELI RODRIGUEZ VELASCO | O11: KAREN DAYANA CASTAÑEDA | Q11: TIC MAT COM CUL SST EMP ETI DER | AG11: TIC | AH11: CRISTINA CASTAÑO CASTILLO | AI11: MAT | AJ11: JULIANA HERNANDEZ BARRERA | AK11: ETI | AL11: NELSON ALFREDO VARGAS MORA | AM11: CUL | AN11: CHRISTIAN CAMILO RODRIGUEZ SALAS | AO11: EMP | AP11: ALBERTO ANTONIO TAPIA TORRES | AS11: SST | AT11: DEISY JULIETH GARCIA CASTAÑEDA | AW11: COM | AX11: =IFERROR(VLOOKUP(A11,_p7_2025,2,FALSE),"") -> CESAR AUGUSTO BERMEO | BA11: DER | BB11: =VLOOKUP(A11,_p8_2025,2,FALSE) -> LAURA STHEPHANIA SANCHEZ PABON | BU11: 65 | BV11: actual
A12: 3186303 | B12: TECNICO | C12: 57 | D12: SERVICIOS Y OPERACIONES MICROFINANCIERAS | E12: 31/03/2025 | F12: 46021 | G12: 30/06/2026 | K12: MOISES EDGARDO MERIÑO POLO | M12: YERSON ALVEIRO DUARTE VELASCO | O12: DAVID BAUTISTA ROMERO | Q12: SST COM DER ETI CUL EMP MAT TIC | AG12: SST | AH12: DEISY JULIETH GARCIA CASTAÑEDA | AI12: COM | AJ12: JORGE ARMANDO PIEDRAHITA CABRERA | AK12: CUL | AL12: MELISSA ANDREA LAITON GARNICA | AM12: ETI | AN12: OLGA STELLA PARDO SARAY | AO12: EMP | AP12: LUIS ARTURO BASTIDAS | AS12: DER | AT12: HECTOR ANDRES CIPAMOCHA CENTENO | AW12: TIC | AX12: =IFERROR(VLOOKUP(A12,_p7_2025,2,FALSE),"") -> ANGELICA JANETH RODRIGUEZ ALONSO | BA12: MAT | BB12: =VLOOKUP(A12,_p8_2025,2,FALSE) -> ELKIN DURAN MANCIPE | BU12: 20 | BV12: actual
A13: 3186304 | B13: TECNICO | C13: 73 | D13: SERVICIOS Y OPERACIONES MICROFINANCIERAS | E13: 31/03/2025 | F13: 46021 | G13: 30/06/2026 | K13: MOISES EDGARDO MERIÑO POLO | M13: YERSON ALVEIRO DUARTE VELASCO | O13: DAVID BAUTISTA ROMERO | Q13: SST COM DER ETI CUL EMP MAT TIC | AG13: SST | AH13: DEISY JULIETH GARCIA CASTAÑEDA | AI13: COM | AJ13: CESAR AUGUSTO BERMEO | AK13: CUL | AL13: MELISSA ANDREA LAITON GARNICA | AM13: ETI | AN13: IVAN DARIO RODRIGUEZ BUSTAMANTE | AO13: EMP | AP13: ESTEFANIA SANDOVAL CRUZ | AS13: DER | AT13: HECTOR ANDRES CIPAMOCHA CENTENO | AW13: TIC | AX13: =IFERROR(VLOOKUP(A13,_p7_2025,2,FALSE),"") -> ANGELICA JANETH RODRIGUEZ ALONSO | BA13: MAT | BB13: =VLOOKUP(A13,_p8_2025,2,FALSE) -> WILDER JULIAN ARIAS HERNANDEZ | BU13: 20 | BV13: actual
A14: 3186305 | B14: TECNICO | C14: 52 | D14: SERVICIOS Y OPERACIONES MICROFINANCIERAS | E14: 31/03/2025 | F14: 46021 | G14: 30/06/2026 | K14: MOISES EDGARDO MERIÑO POLO | M14: YERSON ALVEIRO DUARTE VELASCO | N14: JEIMMY LILIANA CASTILLO GARZON | O14: JHONY ARMANDO RIOS | Q14: SST COM DER ETI CUL EMP MAT TIC | AG14: SST | AH14: DEISY JULIETH GARCIA CASTAÑEDA | AI14: COM | AJ14: CESAR AUGUSTO BERMEO | AK14: CUL | AL14: CHRISTIAN CAMILO RODRIGUEZ SALAS | AM14: ETI | AN14: OLGA STELLA PARDO SARAY | AO14: EMP | AP14: ESTEFANIA SANDOVAL CRUZ | AS14: DER | AT14: MARIA CAROLINA GOMEZ CALLE | AW14: TIC | AX14: =IFERROR(VLOOKUP(A14,_p7_2025,2,FALSE),"") -> CRISTINA CASTAÑO CASTILLO | BA14: MAT | BB14: =VLOOKUP(A14,_p8_2025,2,FALSE) -> WILDER JULIAN ARIAS HERNANDEZ | BU14: 34 | BV14: jeimy
A15: 3167875 | B15: TECNICO | C15: 51 | D15: ASESORIA COMERCIAL | E15: 01/04/2025 | F15: 46022 | G15: 31/12/2025 | K15: KEBIN CUESTA RENTERIA | M15: LUZ MERY ROZO GUTIERREZ | N15: JEIMMY LILIANA CASTILLO GARZON | O15: JHONY ARMANDO RIOS | Q15: TIC EMP MAT CUL ETI COM SST CIE DER | AG15: TIC | AH15: ERICK RUIZ NOREÑA | AI15: EMP | AJ15: ESTEFANIA SANDOVAL CRUZ | AK15: MAT | AL15: JULIANA HERNANDEZ BARRERA | AM15: CIE | AN15: LAURA SOFIA PAEZ GALLO | AO15: CUL | AP15: CHRISTIAN CAMILO RODRIGUEZ SALAS | AS15: ETI | AT15: NELSON ALFREDO VARGAS MORA | AU15: COM | AV15: CESAR AUGUSTO BERMEO | AW15: SST | AX15: =IFERROR(VLOOKUP(A15,_p7_2025,2,FALSE),"") -> DEISY JULIETH GARCIA CASTAÑEDA | BA15: DER | BB15: =VLOOKUP(A15,_p8_2025,2,FALSE) -> LAURA STHEPHANIA SANCHEZ PABON | BU15: 43 | BV15: jeimy
A16: 3167876 | B16: TECNICO | C16: 42 | D16: ASESORIA COMERCIAL | E16: 01/04/2025 | F16: 46022 | G16: 31/12/2025 | K16: KEBIN CUESTA RENTERIA | M16: LUZ MERY ROZO GUTIERREZ | N16: JEIMMY LILIANA CASTILLO GARZON | O16: JHONY ARMANDO RIOS | Q16: TIC EMP MAT CUL ETI COM SST CIE DER | AG16: TIC | AH16: ERICK RUIZ NOREÑA | AI16: EMP | AJ16: ESTEFANIA SANDOVAL CRUZ | AK16: MAT | AL16: ELKIN DURAN MANCIPE | AM16: CIE | AN16: LAURA SOFIA PAEZ GALLO | AO16: ETI | AP16: IVAN DARIO RODRIGUEZ BUSTAMANTE | AS16: CUL | AT16: CHRISTIAN CAMILO RODRIGUEZ SALAS | AU16: COM | AV16: NELLY BLANCO RODRIGUEZ | AW16: SST | AX16: =IFERROR(VLOOKUP(A16,_p7_2025,2,FALSE),"") -> DEISY JULIETH GARCIA CASTAÑEDA | BA16: DER | BB16: =VLOOKUP(A16,_p8_2025,2,FALSE) -> LAURA STHEPHANIA SANCHEZ PABON | BU16: 36 | BV16: jeimy
A17: 3167877 | B17: TECNICO | C17: 56 | D17: ASESORIA COMERCIAL | E17: 01/04/2025 | F17: 46022 | G17: 31/12/2025 | K17: KEBIN CUESTA RENTERIA | M17: LUZ MERY ROZO GUTIERREZ | N17: JEIMMY LILIANA CASTILLO GARZON | O17: JHONY ARMANDO RIOS | Q17: TIC EMP MAT CUL ETI COM SST CIE DER | AG17: TIC | AH17: ERICK RUIZ NOREÑA | AI17: EMP | AJ17: ESTEFANIA SANDOVAL CRUZ | AK17: MAT | AL17: JULIANA HERNANDEZ BARRERA | AM17: CIE | AN17: LAURA SOFIA PAEZ GALLO | AO17: CUL | AP17: MELISSA ANDREA LAITON GARNICA | AS17: ETI | AT17: OLGA STELLA PARDO SARAY | AU17: COM | AV17: NELLY BLANCO RODRIGUEZ | AW17: SST | AX17: =IFERROR(VLOOKUP(A17,_p7_2025,2,FALSE),"") -> JORGE IVAN PEREZ GAITAN | BA17: DER | BB17: =VLOOKUP(A17,_p8_2025,2,FALSE) -> MARIA CAROLINA GOMEZ CALLE | BU17: 48 | BV17: jeimy
A18: 2977135 | B18: TECNOLOGO | C18: 20 | D18: DESARROLLO MULTIMEDIA Y WEB | E18: 14/05/2024 | F18: =IF( OR(((ROUND((G18-E18)/30,0))=27),((ROUND((G18-E18)/30,0))=15)), EDATE(G18,-6), IF( (ROUND((G18-E18)/30,0))=12, EDATE(G18,-3), IF( (ROUND((G18-E18)/30,0))=9, EDATE(G18,0),"CALCULAR"))) -> 46066 | G18: 13/08/2026 | H18: HELDA MARINA SEPULVEDA VEGA | I18: HELDA MARINA SEPULVEDA VEGA | J18: OLGA STELLA PARDO | M18: HELDA MARINA SEPULVEDA VEGA | N18: ANGELA JULIETTE SILVA VELANDIA | O18: ANGELA JULIETTE SILVA VELANDIA | Q18: MAT COM TIC INV FIS CUL ETI SST EMP DER | R18: MAT TIC COM FIS SST INV CUL DER ETI EMP | S18: CUL | T18: MELISSA LAITON LAITON GARNICA | U18: EMP | V18: JOHN FRANZ RINCON PENA | W18: COM | X18: CATHERINE LOZADA OTALORA | Y18: ETI | Z18: NELSON ALFREDO VARGAS MORA | AA18: DER | AB18: MARIA CAROLINA GOMEZ CALLE | AE18: MAT | AF18: ELKIN DURAN MANCIPE | AG18: TIC | AH18: ANGELICA JANETH RODRIGUEZ ALONSO | AK18: INV | AL18: CINDY YOHANA BOHORQUEZ GARZON | AO18: FIS | AP18: CAMILO ERNESTO CALDERON GALINDO | AW18: SST | AX18: =IFERROR(VLOOKUP(A18,_p7_2025,2,FALSE),"") -> DEISY JULIETH GARCIA CASTAÑEDA | BV18: Terminó
A19: 2977136 | B19: TECNOLOGO | C19: 25 | D19: DESARROLLO MULTIMEDIA Y WEB | E19: 14/05/2024 | F19: =IF( OR(((ROUND((G19-E19)/30,0))=27),((ROUND((G19-E19)/30,0))=15)), EDATE(G19,-6), IF( (ROUND((G19-E19)/30,0))=12, EDATE(G19,-3), IF( (ROUND((G19-E19)/30,0))=9, EDATE(G19,0),"CALCULAR"))) -> 46066 | G19: 13/08/2026 | H19: HELDA MARINA SEPULVEDA VEGA | I19: HELDA MARINA SEPULVEDA VEGA | J19: OLGA STELLA PARDO | M19: HELDA MARINA SEPULVEDA VEGA | N19: ANGELA JULIETTE SILVA VELANDIA | O19: ANGELA JULIETTE SILVA VELANDIA | Q19: MAT COM TIC INV FIS CUL ETI SST EMP DER | R19: MAT TIC COM FIS SST INV CUL DER ETI EMP | S19: CUL | T19: YANIS ESTER PEREZ YEPES | U19: FIS | V19: JONATAN LOPEZ CASTILLO | W19: COM | X19: CATHERINE LOZADA OTALORA | Y19: ETI | Z19: LISET NUNEZ RODRIGUEZ | AA19: EMP | AB19: LUIS ARTURO BASTIDAS | AE19: MAT | AF19: ELKIN DURAN MANCIPE | AG19: TIC | AH19: ERICK RUIZ NOREÑA | AK19: INV | AL19: CINDY YOHANA BOHORQUEZ GARZON | AO19: SST | AP19: JORGE IVAN PEREZ GAITAN | AW19: DER | AX19: =IFERROR(VLOOKUP(A19,_p7_2025,2,FALSE),"") -> MARIA CAROLINA GOMEZ CALLE | BV19: Terminó
A20: 2977137 | B20: TECNOLOGO | C20: 20 | D20: DESARROLLO MULTIMEDIA Y WEB | E20: 14/05/2024 | F20: =IF( OR(((ROUND((G20-E20)/30,0))=27),((ROUND((G20-E20)/30,0))=15)), EDATE(G20,-6), IF( (ROUND((G20-E20)/30,0))=12, EDATE(G20,-3), IF( (ROUND((G20-E20)/30,0))=9, EDATE(G20,0),"CALCULAR"))) -> 46066 | G20: 13/08/2026 | H20: HELDA MARINA SEPULVEDA VEGA | I20: HELDA MARINA SEPULVEDA VEGA | J20: OLGA STELLA PARDO | M20: HELDA MARINA SEPULVEDA VEGA | N20: ANGELA JULIETTE SILVA VELANDIA | O20: ANGELA JULIETTE SILVA VELANDIA | Q20: MAT COM TIC INV FIS CUL ETI SST EMP DER | R20: MAT TIC COM FIS SST INV CUL DER ETI EMP | S20: CUL | T20: MELISSA LAITON LAITON GARNICA | U20: FIS | V20: JONATAN LOPEZ CASTILLO | W20: EMP | X20: LUIS ARTURO BASTIDAS | Y20: ETI | Z20: IVAN DARIO RODRIGUEZ BUSTAMANTE | AA20: INV | AB20: CINDY YOHANA BOHORQUEZ GARZON | AE20: MAT | AF20: JULIANA HERNANDEZ BARRERA | AG20: COM | AH20: JORGE ARMANDO PIEDRAHITA CABRERA | AK20: TIC | AL20: CRISTINA CASTAÑO CASTILLO | AO20: SST | AP20: DEISY JULIETH GARCIA CASTAÑEDA | AW20: DER | AX20: =IFERROR(VLOOKUP(A20,_p7_2025,2,FALSE),"") -> HECTOR ANDRES CIPAMOCHA CENTENO | BV20: Terminó
A21: 2977138 | B21: TECNOLOGO | C21: 25 | D21: DESARROLLO MULTIMEDIA Y WEB | E21: 14/05/2024 | F21: =IF( OR(((ROUND((G21-E21)/30,0))=27),((ROUND((G21-E21)/30,0))=15)), EDATE(G21,-6), IF( (ROUND((G21-E21)/30,0))=12, EDATE(G21,-3), IF( (ROUND((G21-E21)/30,0))=9, EDATE(G21,0),"CALCULAR"))) -> 46066 | G21: 13/08/2026 | H21: HELDA MARINA SEPULVEDA VEGA | I21: HELDA MARINA SEPULVEDA VEGA | J21: OLGA STELLA PARDO | M21: HELDA MARINA SEPULVEDA VEGA | N21: ANGELA JULIETTE SILVA VELANDIA | O21: ANGELA JULIETTE SILVA VELANDIA | Q21: MAT COM TIC INV FIS CUL ETI SST EMP DER | R21: MAT TIC COM FIS SST INV CUL DER ETI EMP | S21: CUL | T21: YANIS ESTER PEREZ YEPES | U21: FIS | V21: JONATAN LOPEZ CASTILLO | W21: EMP | X21: CLAUDIA ALICIA HERNANDEZ MESA | Y21: ETI | Z21: IVAN DARIO RODRIGUEZ BUSTAMANTE | AA21: INV | AB21: CINDY YOHANA BOHORQUEZ GARZON | AC21: DER | AD21: HECTOR ANDRES CIPAMOCHA CENTENO | AE21: MAT | AF21: ELKIN DURAN MANCIPE | AG21: SST | AH21: MARINELLA DIAZ ACOSTA | AK21: COM | AL21: CESAR AUGUSTO BERMEO | AW21: TIC | AX21: =IFERROR(VLOOKUP(A21,_p7_2025,2,FALSE),"") -> ANGELICA JANETH RODRIGUEZ ALONSO | BV21: Terminó
A22: 2977225 | B22: TECNOLOGO | C22: 33 | D22: DESARROLLO DE MEDIOS GRAFICOS VISUALES | E22: 14/05/2024 | F22: =IF( OR(((ROUND((G22-E22)/30,0))=27),((ROUND((G22-E22)/30,0))=15)), EDATE(G22,-6), IF( (ROUND((G22-E22)/30,0))=12, EDATE(G22,-3), IF( (ROUND((G22-E22)/30,0))=9, EDATE(G22,0),"CALCULAR"))) -> 46066 | G22: 13/08/2026 | H22: JULIAN DAVID RODRIGUEZ GARZON | I22: JULIAN DAVID RODRIGUEZ GARZON | J22: GUSTAVO ADOLFO MORALES CAMARGO | L22: JULIAN DAVID RODRIGUEZ GARZON | M22: WANDA POSADA PAZ | N22: ANGELA JULIETTE SILVA VELANDIA | O22: ANGELA JULIETTE SILVA VELANDIA | Q22: TIC MAT COM SST DER EMP INV FIS CUL ETI | R22: MAT TIC COM FIS SST INV CUL DER ETI EMP | S22: TIC | T22: EULISES MOGOLLON ORTIZ | U22: COM | V22: CATHERINE LOZADA OTALORA | W22: ETI | X22: CLAUDIA YAMILE MORALES CASTRO | AA22: SST | AB22: JORGE IVAN PEREZ GAITAN | AC22: MAT | AD22: ELKIN DURAN MANCIPE | AE22: DER | AF22: MARIA CAROLINA GOMEZ CALLE | AG22: EMP | AH22: LUIS ARTURO BASTIDAS | AK22: CUL | AL22: MELISSA ANDREA LAITON GARNICA | AO22: FIS | AP22: CAMILO ERNESTO CALDERON GALINDO | AX22: =IFERROR(VLOOKUP(A22,_p7_2025,2,FALSE),"") | BA22: INV | BB22: =VLOOKUP(A22,_p8_2025,2,FALSE) -> CINDY YOHANA BOHORQUEZ GARZON | BV22: Terminó
A23: 2977226 | B23: TECNOLOGO | C23: 29 | D23: DESARROLLO DE MEDIOS GRAFICOS VISUALES | E23: 14/05/2024 | F23: =IF( OR(((ROUND((G23-E23)/30,0))=27),((ROUND((G23-E23)/30,0))=15)), EDATE(G23,-6), IF( (ROUND((G23-E23)/30,0))=12, EDATE(G23,-3), IF( (ROUND((G23-E23)/30,0))=9, EDATE(G23,0),"CALCULAR"))) -> 46066 | G23: 13/08/2026 | H23: JULIAN DAVID RODRIGUEZ GARZON | I23: JULIAN DAVID RODRIGUEZ GARZON | J23: GUSTAVO ADOLFO MORALES CAMARGO | L23: JULIAN DAVID RODRIGUEZ GARZON | M23: WANDA POSADA PAZ | N23: ANGELA JULIETTE SILVA VELANDIA | O23: ANGELA JULIETTE SILVA VELANDIA | Q23: TIC MAT COM SST DER EMP INV FIS CUL ETI | R23: MAT TIC COM FIS SST INV CUL DER ETI EMP | S23: TIC | T23: CRISTINA CASTAÑO CASTILLO | U23: COM | V23: JORGE ARMANDO PIEDRAHITA CABRERA | W23: ETI | X23: LISET NUNEZ RODRIGUEZ | AA23: SST | AB23: JORGE IVAN PEREZ GAITAN | AC23: MAT | AD23: ELKIN DURAN MANCIPE | AE23: DER | AF23: HECTOR ANDRES CIPAMOCHA CENTENO | AG23: EMP | AH23: ALBERTO ANTONIO TAPIA TORRES | AK23: CUL | AL23: MELISSA ANDREA LAITON GARNICA | AO23: FIS | AP23: CAMILO ERNESTO CALDERON GALINDO | AX23: =IFERROR(VLOOKUP(A23,_p7_2025,2,FALSE),"") | BA23: INV | BB23: =VLOOKUP(A23,_p8_2025,2,FALSE) -> CINDY YOHANA BOHORQUEZ GARZON | BV23: Terminó
A24: 2977227 | B24: TECNOLOGO | C24: 35 | D24: DESARROLLO DE MEDIOS GRAFICOS VISUALES | E24: 14/05/2024 | F24: =IF( OR(((ROUND((G24-E24)/30,0))=27),((ROUND((G24-E24)/30,0))=15)), EDATE(G24,-6), IF( (ROUND((G24-E24)/30,0))=12, EDATE(G24,-3), IF( (ROUND((G24-E24)/30,0))=9, EDATE(G24,0),"CALCULAR"))) -> 46066 | G24: 13/08/2026 | H24: JULIAN DAVID RODRIGUEZ GARZON | I24: JULIAN DAVID RODRIGUEZ GARZON | J24: GUSTAVO ADOLFO MORALES CAMARGO | L24: JULIAN DAVID RODRIGUEZ GARZON | M24: WANDA POSADA PAZ | N24: ANGELA JULIETTE SILVA VELANDIA | O24: ANGELA JULIETTE SILVA VELANDIA | Q24: TIC MAT COM SST DER EMP INV FIS CUL ETI | R24: MAT TIC COM FIS SST INV CUL DER ETI EMP | S24: TIC | T24: CRISTINA CASTAÑO CASTILLO | U24: COM | V24: JORGE ARMANDO PIEDRAHITA CABRERA | W24: ETI | X24: NELSON ALFREDO VARGAS MORA | Y24: SST | Z24: JORGE IVAN PEREZ GAITAN | AA24: CUL | AB24: CHRISTIAN CAMILO RODRIGUEZ SALAS | AC24: MAT | AD24: ELKIN DURAN MANCIPE | AE24: DER | AF24: HECTOR ANDRES CIPAMOCHA CENTENO | AG24: EMP | AH24: ALBERTO ANTONIO TAPIA TORRES | AO24: FIS | AP24: CAMILO ERNESTO CALDERON GALINDO | AX24: =IFERROR(VLOOKUP(A24,_p7_2025,2,FALSE),"") | BA24: INV | BB24: =VLOOKUP(A24,_p8_2025,2,FALSE) -> CINDY YOHANA BOHORQUEZ GARZON | BV24: Terminó
A25: 2977228 | B25: TECNOLOGO | C25: 34 | D25: DESARROLLO DE MEDIOS GRAFICOS VISUALES | E25: 14/05/2024 | F25: =IF( OR(((ROUND((G25-E25)/30,0))=27),((ROUND((G25-E25)/30,0))=15)), EDATE(G25,-6), IF( (ROUND((G25-E25)/30,0))=12, EDATE(G25,-3), IF( (ROUND((G25-E25)/30,0))=9, EDATE(G25,0),"CALCULAR"))) -> 46066 | G25: 13/08/2026 | H25: LEYDY NAHIR FONSECA CARDENAS | I25: LEYDY NAHIR FONSECA CARDENAS | J25: GUSTAVO ADOLFO MORALES CAMARGO | M25: LEYDY NAHIR FONSECA CARDENAS | N25: ANGELA JULIETTE SILVA VELANDIA | O25: ANGELA JULIETTE SILVA VELANDIA | Q25: TIC MAT COM SST DER EMP INV FIS CUL ETI | R25: MAT TIC COM FIS SST INV CUL DER ETI EMP | S25: TIC | T25: EULISES MOGOLLON ORTIZ | U25: COM | V25: JORGE ARMANDO PIEDRAHITA CABRERA | W25: ETI | X25: NELLYS JANETH BLANCO RODRIGUEZ | Y25: SST | Z25: LORENA SUAREZ CORREA | AA25: CUL | AB25: CHRISTIAN CAMILO RODRIGUEZ SALAS | AC25: MAT | AD25: JULIANA HERNANDEZ BARRERA | AE25: DER | AF25: MARIA CAROLINA GOMEZ CALLE | AG25: EMP | AH25: ALBERTO ANTONIO TAPIA TORRES | AW25: FIS | AX25: =IFERROR(VLOOKUP(A25,_p7_2025,2,FALSE),"") -> CAMILO ERNESTO CALDERON GALINDO | BA25: INV | BB25: =VLOOKUP(A25,_p8_2025,2,FALSE) -> CINDY YOHANA BOHORQUEZ GARZON | BV25: Terminó
A26: 2977229 | B26: TECNOLOGO | C26: 31 | D26: DESARROLLO DE MEDIOS GRAFICOS VISUALES | E26: 14/05/2024 | F26: =IF( OR(((ROUND((G26-E26)/30,0))=27),((ROUND((G26-E26)/30,0))=15)), EDATE(G26,-6), IF( (ROUND((G26-E26)/30,0))=12, EDATE(G26,-3), IF( (ROUND((G26-E26)/30,0))=9, EDATE(G26,0),"CALCULAR"))) -> 46066 | G26: 13/08/2026 | H26: LEYDY NAHIR FONSECA CARDENAS | I26: LEYDY NAHIR FONSECA CARDENAS | J26: GUSTAVO ADOLFO MORALES CAMARGO | M26: LEYDY NAHIR FONSECA CARDENAS | N26: DAVID BAUTISTA ROMERO | O26: DAVID BAUTISTA ROMERO | Q26: TIC MAT COM SST DER EMP INV FIS CUL ETI | R26: MAT TIC COM FIS SST INV CUL DER ETI EMP | S26: TIC | T26: CRISTINA CASTAÑO CASTILLO | U26: COM | V26: CATHERINE LOZADA OTALORA | W26: ETI | X26: IVAN DARIO RODRIGUEZ BUSTAMANTE | Y26: SST | Z26: JORGE IVAN PEREZ GAITAN | AA26: CUL | AB26: CHRISTIAN CAMILO RODRIGUEZ SALAS | AE26: MAT | AF26: ELKIN DURAN MANCIPE | AG26: EMP | AH26: ALBERTO ANTONIO TAPIA TORRES | AK26: DER | AL26: MARIA CAROLINA GOMEZ CALLE | AW26: FIS | AX26: =IFERROR(VLOOKUP(A26,_p7_2025,2,FALSE),"") -> CAMILO ERNESTO CALDERON GALINDO | BA26: INV | BB26: =VLOOKUP(A26,_p8_2025,2,FALSE) -> CINDY YOHANA BOHORQUEZ GARZON | BU26: 12 | BV26: actual
A27: 2977230 | B27: TECNOLOGO | C27: 23 | D27: DESARROLLO DE MEDIOS GRAFICOS VISUALES | E27: 14/05/2024 | F27: =IF( OR(((ROUND((G27-E27)/30,0))=27),((ROUND((G27-E27)/30,0))=15)), EDATE(G27,-6), IF( (ROUND((G27-E27)/30,0))=12, EDATE(G27,-3), IF( (ROUND((G27-E27)/30,0))=9, EDATE(G27,0),"CALCULAR"))) -> 46066 | G27: 13/08/2026 | H27: LEYDY NAHIR FONSECA CARDENAS | I27: LEYDY NAHIR FONSECA CARDENAS | J27: GUSTAVO ADOLFO MORALES CAMARGO | M27: LEYDY NAHIR FONSECA CARDENAS | N27: DAVID BAUTISTA ROMERO | O27: DAVID BAUTISTA ROMERO | Q27: TIC MAT COM SST DER EMP INV FIS CUL ETI | R27: MAT TIC COM FIS SST INV CUL DER ETI EMP | S27: TIC | T27: CRISTINA CASTAÑO CASTILLO | U27: CUL | V27: YANIS ESTER PEREZ YEPES | W27: ETI | X27: IVAN DARIO RODRIGUEZ BUSTAMANTE | AA27: INV | AB27: CINDY YOHANA BOHORQUEZ GARZON | AC27: SST | AD27: DEISY JULIETH GARCIA CASTAÑEDA | AE27: MAT | AF27: JULIANA HERNANDEZ BARRERA | AG27: EMP | AH27: ALBERTO ANTONIO TAPIA TORRES | AK27: COM | AL27: CESAR AUGUSTO BERMEO | AO27: DER | AP27: HECTOR ANDRES CIPAMOCHA CENTENO | AW27: FIS | AX27: =IFERROR(VLOOKUP(A27,_p7_2025,2,FALSE),"") -> CAMILO ERNESTO CALDERON GALINDO | BU27: 12 | BV27: actual
A28: 2977457 | B28: TECNOLOGO | C28: 27 | D28: ANALISIS Y DESARROLLO DE SOFTWARE | E28: 14/05/2024 | F28: =IF( OR(((ROUND((G28-E28)/30,0))=27),((ROUND((G28-E28)/30,0))=15)), EDATE(G28,-6), IF( (ROUND((G28-E28)/30,0))=12, EDATE(G28,-3), IF( (ROUND((G28-E28)/30,0))=9, EDATE(G28,0),"CALCULAR"))) -> 46066 | G28: 13/08/2026 | H28: JHON MANUEL SOTO CALA | I28: JHON MANUEL SOTO CALA | J28: MARINELLA DIAZ ACOSTA | M28: EDUER PABON MORALES | N28: DAVID BAUTISTA ROMERO | O28: DAVID BAUTISTA ROMERO | Q28: MAT TIC COM INV FIS EMP ETI SST CUL DER | R28: MAT TIC COM FIS SST INV CUL DER ETI EMP | S28: ETI | T28: STEPHANIE DURAN BARRAGAN | U28: CUL | V28: MELISSA LAITON LAITON GARNICA | W28: EMP | X28: CLAUDIA ALICIA HERNANDEZ MESA | Y28: SST | Z28: LORENA SUAREZ CORREA | AA28: INV | AB28: FRANCI PAOLA LOZANO PIRAQUIVE | AC28: MAT | AD28: ELKIN DURAN MANCIPE | AE28: FIS | AF28: CAMILO ERNESTO CALDERON GALINDO | AG28: TIC | AH28: ANGELICA JANETH RODRIGUEZ ALONSO | AK28: DER | AL28: LAURA STHEPHANIA SANCHEZ PABON | AX28: =IFERROR(VLOOKUP(A28,_p7_2025,2,FALSE),"") | BA28: COM | BB28: =VLOOKUP(A28,_p8_2025,2,FALSE) -> JORGE ARMANDO PIEDRAHITA | BU28: 12 | BV28: actual
A29: 2977458 | B29: TECNOLOGO | C29: 36 | D29: ANALISIS Y DESARROLLO DE SOFTWARE | E29: 14/05/2024 | F29: =IF( OR(((ROUND((G29-E29)/30,0))=27),((ROUND((G29-E29)/30,0))=15)), EDATE(G29,-6), IF( (ROUND((G29-E29)/30,0))=12, EDATE(G29,-3), IF( (ROUND((G29-E29)/30,0))=9, EDATE(G29,0),"CALCULAR"))) -> 46066 | G29: 13/08/2026 | H29: ANA MILENA MOSQUERA SEVILLA | I29: ANA MILENA MOSQUERA SEVILLA | J29: MARINELLA DIAZ ACOSTA | M29: ANA MILENA MOSQUERA SEVILLA | N29: DAVID BAUTISTA ROMERO | O29: DAVID BAUTISTA ROMERO | Q29: MAT TIC COM INV FIS EMP ETI SST CUL DER | R29: MAT TIC COM FIS SST INV CUL DER ETI EMP | S29: ETI | T29: STEPHANIE DURAN BARRAGAN | U29: CUL | V29: MELISSA LAITON LAITON GARNICA | W29: EMP | X29: NUBIA STELLA CARRENO AMAYA | Y29: SST | Z29: LORENA SUAREZ CORREA | AA29: DER | AB29: HECTOR ANDRES CIPAMOCHA CENTENO | AC29: MAT | AD29: JULIANA HERNANDEZ BARRERA | AE29: TIC | AF29: CRISTINA CASTAÑO CASTILLO | AG29: FIS | AH29: CAMILO ERNESTO CALDERON GALINDO | AK29: COM | AL29: ALBA LUCIA BELTRAN | AS29: INV | AT29: CINDY YOHANA BOHORQUEZ GARZON | AX29: =IFERROR(VLOOKUP(A29,_p7_2025,2,FALSE),"") | BU29: 12 | BV29: actual
A30: 2977459 | B30: TECNOLOGO | C30: 35 | D30: ANALISIS Y DESARROLLO DE SOFTWARE | E30: 14/05/2024 | F30: =IF( OR(((ROUND((G30-E30)/30,0))=27),((ROUND((G30-E30)/30,0))=15)), EDATE(G30,-6), IF( (ROUND((G30-E30)/30,0))=12, EDATE(G30,-3), IF( (ROUND((G30-E30)/30,0))=9, EDATE(G30,0),"CALCULAR"))) -> 46066 | G30: 13/08/2026 | H30: ANA MILENA MOSQUERA SEVILLA | I30: ANA MILENA MOSQUERA SEVILLA | J30: MARINELLA DIAZ ACOSTA | M30: ANA MILENA MOSQUERA SEVILLA | N30: DAVID BAUTISTA ROMERO | O30: DAVID BAUTISTA ROMERO | Q30: MAT TIC COM INV FIS EMP ETI SST CUL DER | R30: MAT TIC COM FIS SST INV CUL DER ETI EMP | S30: ETI | T30: STEPHANIE DURAN BARRAGAN | U30: CUL | V30: YANIS ESTER PEREZ YEPES | W30: EMP | X30: ESTEFANIA SANDOVAL CRUZ | Y30: SST | Z30: LORENA SUAREZ CORREA | AA30: DER | AB30: HECTOR ANDRES CIPAMOCHA CENTENO | AC30: MAT | AD30: JULIANA HERNANDEZ BARRERA | AE30: TIC | AF30: ERICK RUIZ NOREÑA | AG30: FIS | AH30: CAMILO ERNESTO CALDERON GALINDO | AK30: COM | AL30: ALBA LUCIA BELTRAN | AS30: INV | AT30: CINDY YOHANA BOHORQUEZ GARZON | AX30: =IFERROR(VLOOKUP(A30,_p7_2025,2,FALSE),"") | BU30: 12 | BV30: actual
A31: 2977460 | B31: TECNOLOGO | C31: 37 | D31: ANALISIS Y DESARROLLO DE SOFTWARE | E31: 14/05/2024 | F31: =IF( OR(((ROUND((G31-E31)/30,0))=27),((ROUND((G31-E31)/30,0))=15)), EDATE(G31,-6), IF( (ROUND((G31-E31)/30,0))=12, EDATE(G31,-3), IF( (ROUND((G31-E31)/30,0))=9, EDATE(G31,0),"CALCULAR"))) -> 46066 | G31: 13/08/2026 | H31: ANA MILENA MOSQUERA SEVILLA | I31: ANA MILENA MOSQUERA SEVILLA | J31: MARINELLA DIAZ ACOSTA | M31: ANA MILENA MOSQUERA SEVILLA | N31: DAVID BAUTISTA ROMERO | O31: DAVID BAUTISTA ROMERO | Q31: MAT TIC COM INV FIS EMP ETI SST CUL DER | R31: MAT TIC COM FIS SST INV CUL DER ETI EMP | S31: ETI | T31: STEPHANIE DURAN BARRAGAN | U31: CUL | V31: MELISSA LAITON LAITON GARNICA | W31: EMP | X31: LUIS ARTURO BASTIDAS | AA31: SST | AB31: LORENA SUAREZ CORREA | AC31: MAT | AD31: ELKIN DURAN MANCIPE | AE31: TIC | AF31: ERICK RUIZ NOREÑA | AG31: INV | AH31: FRANCI PAOLA LOZANO PIRAQUIVE | AK31: DER | AL31: MARIA CAROLINA GOMEZ CALLE | AW31: FIS | AX31: =IFERROR(VLOOKUP(A31,_p7_2025,2,FALSE),"") -> CAMILO ERNESTO CALDERON GALINDO | BA31: COM | BB31: =VLOOKUP(A31,_p8_2025,2,FALSE) -> CESAR AUGUSTO BERMEO | BU31: 12 | BV31: actual
A32: 2977461 | B32: TECNOLOGO | C32: 38 | D32: ANALISIS Y DESARROLLO DE SOFTWARE | E32: 14/05/2024 | F32: =IF( OR(((ROUND((G32-E32)/30,0))=27),((ROUND((G32-E32)/30,0))=15)), EDATE(G32,-6), IF( (ROUND((G32-E32)/30,0))=12, EDATE(G32,-3), IF( (ROUND((G32-E32)/30,0))=9, EDATE(G32,0),"CALCULAR"))) -> 46066 | G32: 13/08/2026 | H32: ANA MILENA MOSQUERA SEVILLA | I32: ANA MILENA MOSQUERA SEVILLA | J32: MARINELLA DIAZ ACOSTA | M32: ANA MILENA MOSQUERA SEVILLA | N32: DAVID BAUTISTA ROMERO | O32: DAVID BAUTISTA ROMERO | Q32: MAT TIC COM INV FIS EMP ETI SST CUL DER | R32: MAT TIC COM FIS SST INV CUL DER ETI EMP | S32: ETI | T32: STEPHANIE DURAN BARRAGAN | U32: CUL | V32: CHRISTIAN CAMILO RODRIGUEZ SALAS | W32: EMP | X32: ESTEFANIA SANDOVAL CRUZ | Y32: SST | Z32: MARINELLA DIAZ ACOSTA | AA32: DER | AB32: MARIA CAROLINA GOMEZ CALLE | AC32: MAT | AD32: JULIANA HERNANDEZ BARRERA | AE32: TIC | AF32: ERICK RUIZ NOREÑA | AG32: INV | AH32: FRANCI PAOLA LOZANO PIRAQUIVE | AK32: COM | AL32: CESAR AUGUSTO BERMEO | AO32: FIS | AP32: CAMILO ERNESTO CALDERON GALINDO | AX32: =IFERROR(VLOOKUP(A32,_p7_2025,2,FALSE),"") | BU32: 12 | BV32: actual
A33: 2977462 | B33: TECNOLOGO | C33: 32 | D33: ANALISIS Y DESARROLLO DE SOFTWARE | E33: 14/05/2024 | F33: =IF( OR(((ROUND((G33-E33)/30,0))=27),((ROUND((G33-E33)/30,0))=15)), EDATE(G33,-6), IF( (ROUND((G33-E33)/30,0))=12, EDATE(G33,-3), IF( (ROUND((G33-E33)/30,0))=9, EDATE(G33,0),"CALCULAR"))) -> 46066 | G33: 13/08/2026 | H33: ELIZABETH GELVES GELVES | I33: ELIZABETH GELVES GELVES | J33: MARINELLA DIAZ ACOSTA | M33: ELIZABETH GELVES GELVES | N33: DAVID BAUTISTA ROMERO | O33: DAVID BAUTISTA ROMERO | Q33: MAT TIC COM INV FIS EMP ETI SST CUL DER | R33: MAT TIC COM FIS SST INV CUL DER ETI EMP | S33: ETI | T33: STEPHANIE DURAN BARRAGAN | U33: CUL | V33: YANIS ESTER PEREZ YEPES | W33: EMP | X33: CLAUDIA ALICIA HERNANDEZ MESA | Y33: SST | Z33: JORGE IVAN PEREZ GAITAN | AA33: COM | AB33: JORGE ARMANDO PIEDRAHITA CABRERA | AC33: MAT | AD33: JULIANA HERNANDEZ BARRERA | AE33: TIC | AF33: CRISTINA CASTAÑO CASTILLO | AG33: INV | AH33: CINDY YOHANA BOHORQUEZ GARZON | AO33: FIS | AP33: CAMILO ERNESTO CALDERON GALINDO | AW33: DER | AX33: =IFERROR(VLOOKUP(A33,_p7_2025,2,FALSE),"") -> HECTOR ANDRES CIPAMOCHA CENTENO | BU33: 12 | BV33: actual
A34: 2977463 | B34: TECNOLOGO | C34: 29 | D34: ANALISIS Y DESARROLLO DE SOFTWARE | E34: 14/05/2024 | F34: =IF( OR(((ROUND((G34-E34)/30,0))=27),((ROUND((G34-E34)/30,0))=15)), EDATE(G34,-6), IF( (ROUND((G34-E34)/30,0))=12, EDATE(G34,-3), IF( (ROUND((G34-E34)/30,0))=9, EDATE(G34,0),"CALCULAR"))) -> 46066 | G34: 13/08/2026 | H34: ELIZABETH GELVES GELVES | I34: ELIZABETH GELVES GELVES | J34: MARINELLA DIAZ ACOSTA | M34: ELIZABETH GELVES GELVES | N34: DAVID BAUTISTA ROMERO | O34: DAVID BAUTISTA ROMERO | Q34: MAT TIC COM INV FIS EMP ETI SST CUL DER | R34: MAT TIC COM FIS SST INV CUL DER ETI EMP | S34: ETI | T34: STEPHANIE DURAN BARRAGAN | U34: CUL | V34: CHRISTIAN CAMILO RODRIGUEZ SALAS | W34: EMP | X34: NUBIA STELLA CARRENO AMAYA | AA34: SST | AB34: JORGE IVAN PEREZ GAITAN | AC34: MAT | AD34: ELKIN DURAN MANCIPE | AE34: TIC | AF34: CRISTINA CASTAÑO CASTILLO | AG34: INV | AH34: FRANCI PAOLA LOZANO PIRAQUIVE | AK34: DER | AL34: MARIA CAROLINA GOMEZ CALLE | AW34: FIS | AX34: =IFERROR(VLOOKUP(A34,_p7_2025,2,FALSE),"") -> CAMILO ERNESTO CALDERON GALINDO | BA34: COM | BB34: =VLOOKUP(A34,_p8_2025,2,FALSE) -> JORGE ARMANDO PIEDRAHITA | BU34: 12 | BV34: actual
A35: 2977464 | B35: TECNOLOGO | C35: 23 | D35: ANALISIS Y DESARROLLO DE SOFTWARE | E35: 14/05/2024 | F35: =IF( OR(((ROUND((G35-E35)/30,0))=27),((ROUND((G35-E35)/30,0))=15)), EDATE(G35,-6), IF( (ROUND((G35-E35)/30,0))=12, EDATE(G35,-3), IF( (ROUND((G35-E35)/30,0))=9, EDATE(G35,0),"CALCULAR"))) -> 46066 | G35: 13/08/2026 | H35: ELIZABETH GELVES GELVES | I35: ELIZABETH GELVES GELVES | J35: MARINELLA DIAZ ACOSTA | M35: ELIZABETH GELVES GELVES | N35: DAVID BAUTISTA ROMERO | O35: DAVID BAUTISTA ROMERO | Q35: MAT TIC COM INV FIS EMP ETI SST CUL DER | R35: MAT TIC COM FIS SST INV CUL DER ETI EMP | S35: ETI | T35: STEPHANIE DURAN BARRAGAN | U35: CUL | V35: MELISSA LAITON LAITON GARNICA | W35: EMP | X35: NUBIA STELLA CARRENO AMAYA | Y35: SST | Z35: LORENA SUAREZ CORREA | AA35: MAT | AB35: ELKIN DURAN MANCIPE | AC35: TIC | AD35: ERICK RUIZ NOREÑA | AE35: COM | AF35: JORGE ARMANDO PIEDRAHITA CABRERA | AG35: INV | AH35: FRANCI PAOLA LOZANO PIRAQUIVE | AO35: FIS | AP35: CAMILO ERNESTO CALDERON GALINDO | AW35: DER | AX35: =IFERROR(VLOOKUP(A35,_p7_2025,2,FALSE),"") -> LAURA STHEPHANIA SANCHEZ PABON | BU35: 12 | BV35: actual
A36: 2977465 | B36: TECNOLOGO | C36: 25 | D36: ANALISIS Y DESARROLLO DE SOFTWARE | E36: 14/05/2024 | F36: =IF( OR(((ROUND((G36-E36)/30,0))=27),((ROUND((G36-E36)/30,0))=15)), EDATE(G36,-6), IF( (ROUND((G36-E36)/30,0))=12, EDATE(G36,-3), IF( (ROUND((G36-E36)/30,0))=9, EDATE(G36,0),"CALCULAR"))) -> 46066 | G36: 13/08/2026 | H36: ELIZABETH GELVES GELVES | I36: ELIZABETH GELVES GELVES | J36: LUIS ARTURO BASTIDAS | M36: ELIZABETH GELVES GELVES | N36: DAVID BAUTISTA ROMERO | O36: DAVID BAUTISTA ROMERO | Q36: MAT TIC COM INV FIS EMP ETI SST CUL DER | R36: MAT TIC COM FIS SST INV CUL DER ETI EMP | S36: ETI | T36: STEPHANIE DURAN BARRAGAN | U36: CUL | V36: MELISSA LAITON LAITON GARNICA | W36: EMP | X36: ESTEFANIA SANDOVAL CRUZ | Y36: SST | Z36: MARINELLA DIAZ ACOSTA | AA36: MAT | AB36: JULIANA HERNANDEZ BARRERA | AC36: TIC | AD36: CRISTINA CASTAÑO CASTILLO | AE36: COM | AF36: JORGE ARMANDO PIEDRAHITA CABRERA | AG36: INV | AH36: CINDY YOHANA BOHORQUEZ GARZON | AK36: FIS | AL36: CAMILO ERNESTO CALDERON GALINDO | AO36: DER | AP36: HECTOR ANDRES CIPAMOCHA CENTENO | AX36: =IFERROR(VLOOKUP(A36,_p7_2025,2,FALSE),"") | BU36: 12 | BV36: actual
A37: 2977466 | B37: TECNOLOGO | C37: 29 | D37: ANALISIS Y DESARROLLO DE SOFTWARE | E37: 14/05/2024 | F37: =IF( OR(((ROUND((G37-E37)/30,0))=27),((ROUND((G37-E37)/30,0))=15)), EDATE(G37,-6), IF( (ROUND((G37-E37)/30,0))=12, EDATE(G37,-3), IF( (ROUND((G37-E37)/30,0))=9, EDATE(G37,0),"CALCULAR"))) -> 46066 | G37: 13/08/2026 | H37: ANDRES RUBIANO CUCARIAN | I37: ANDRES RUBIANO CUCARIAN | J37: LUIS ARTURO BASTIDAS | L37: ANDRES RUBIANO CUCARIAN | M37: JUAN CARLOS GUERRERO MALDONADO | N37: DAVID BAUTISTA ROMERO | O37: DAVID BAUTISTA ROMERO | Q37: MAT TIC COM INV FIS EMP ETI SST CUL DER | R37: MAT TIC COM FIS SST INV CUL DER ETI EMP | S37: ETI | T37: NELLYS JANETH BLANCO RODRIGUEZ | U37: CUL | V37: CHRISTIAN CAMILO RODRIGUEZ SALAS | W37: EMP | X37: ESTEFANIA SANDOVAL CRUZ | Y37: SST | Z37: JORGE IVAN PEREZ GAITAN | AA37: MAT | AB37: JULIANA HERNANDEZ BARRERA | AC37: TIC | AD37: ERICK RUIZ NOREÑA | AE37: COM | AF37: CESAR AUGUSTO BERMEO | AG37: INV | AH37: FRANCI PAOLA LOZANO PIRAQUIVE | AK37: FIS | AL37: CAMILO ERNESTO CALDERON GALINDO | AO37: DER | AP37: HECTOR ANDRES CIPAMOCHA CENTENO | AX37: =IFERROR(VLOOKUP(A37,_p7_2025,2,FALSE),"") | BU37: 12 | BV37: actual
A38: 2977467 | B38: TECNOLOGO | C38: 27 | D38: ANALISIS Y DESARROLLO DE SOFTWARE | E38: 14/05/2024 | F38: =IF( OR(((ROUND((G38-E38)/30,0))=27),((ROUND((G38-E38)/30,0))=15)), EDATE(G38,-6), IF( (ROUND((G38-E38)/30,0))=12, EDATE(G38,-3), IF( (ROUND((G38-E38)/30,0))=9, EDATE(G38,0),"CALCULAR"))) -> 46066 | G38: 13/08/2026 | H38: ANDRES RUBIANO CUCARIAN | I38: ANDRES RUBIANO CUCARIAN | J38: LUIS ARTURO BASTIDAS | L38: ANDRES RUBIANO CUCARIAN | M38: JUAN CARLOS GUERRERO MALDONADO | N38: DAVID BAUTISTA ROMERO | O38: DAVID BAUTISTA ROMERO | Q38: MAT TIC COM INV FIS EMP ETI SST CUL DER | R38: MAT TIC COM FIS SST INV CUL DER ETI EMP | S38: ETI | T38: NELLYS JANETH BLANCO RODRIGUEZ | U38: CUL | V38: YANIS ESTER PEREZ YEPES | W38: EMP | X38: JOHN FRANZ RINCON PENA | Y38: SST | Z38: MARINELLA DIAZ ACOSTA | AA38: MAT | AB38: CINDY CRISTINA CEBALLOS MALDONADO | AC38: TIC | AD38: ERICK RUIZ NOREÑA | AE38: COM | AF38: CESAR AUGUSTO BERMEO | AG38: INV | AH38: CINDY YOHANA BOHORQUEZ GARZON | AK38: FIS | AL38: CAMILO ERNESTO CALDERON GALINDO | AO38: DER | AP38: MARIA CAROLINA GOMEZ CALLE | AX38: =IFERROR(VLOOKUP(A38,_p7_2025,2,FALSE),"") | BU38: 12 | BV38: actual
A39: 2977468 | B39: TECNOLOGO | C39: 28 | D39: ANALISIS Y DESARROLLO DE SOFTWARE | E39: 14/05/2024 | F39: =IF( OR(((ROUND((G39-E39)/30,0))=27),((ROUND((G39-E39)/30,0))=15)), EDATE(G39,-6), IF( (ROUND((G39-E39)/30,0))=12, EDATE(G39,-3), IF( (ROUND((G39-E39)/30,0))=9, EDATE(G39,0),"CALCULAR"))) -> 46066 | G39: 13/08/2026 | H39: ANDRES RUBIANO CUCARIAN | I39: ANDRES RUBIANO CUCARIAN | J39: LUIS ARTURO BASTIDAS | L39: ANDRES RUBIANO CUCARIAN | M39: JUAN CARLOS GUERRERO MALDONADO | N39: JOHAN ENRIQUE ORTEGA AMADO/WILSON QUINTERO ARDILA (TERMINO) | Q39: MAT TIC COM INV FIS EMP ETI SST CUL DER | R39: MAT TIC COM FIS SST INV CUL DER ETI EMP | S39: ETI | T39: NELLYS JANETH BLANCO RODRIGUEZ | U39: COM | V39: CATHERINE LOZADA OTALORA | W39: MAT | X39: JULIANA HERNANDEZ BARRERA | Y39: TIC | Z39: CRISTINA CASTAÑO CASTILLO | AA39: INV | AB39: DIANA MARCELA FIGUEROA FONSECA | AC39: FIS | AD39: CAMILO ERNESTO CALDERON GALINDO | AE39: EMP | AF39: ESTEFANIA SANDOVAL CRUZ | AG39: SST | AH39: JORGE IVAN PEREZ GAITAN | AK39: CUL | AL39: CHRISTIAN CAMILO RODRIGUEZ SALAS | AO39: DER | AP39: MARIA CAROLINA GOMEZ CALLE | AX39: =IFERROR(VLOOKUP(A39,_p7_2025,2,FALSE),"") | BV39: Terminó
A40: 2977469 | B40: TECNOLOGO | C40: 40 | D40: ANALISIS Y DESARROLLO DE SOFTWARE | E40: 14/05/2024 | F40: =IF( OR(((ROUND((G40-E40)/30,0))=27),((ROUND((G40-E40)/30,0))=15)), EDATE(G40,-6), IF( (ROUND((G40-E40)/30,0))=12, EDATE(G40,-3), IF( (ROUND((G40-E40)/30,0))=9, EDATE(G40,0),"CALCULAR"))) -> 46066 | G40: 13/08/2026 | H40: ANA MILENA MOSQUERA SEVILLA | I40: ANA MILENA MOSQUERA SEVILLA | J40: LUIS ARTURO BASTIDAS | M40: ANA MILENA MOSQUERA SEVILLA | N40: JOHAN ENRIQUE ORTEGA AMADO/WILSON QUINTERO ARDILA (TERMINO) | Q40: MAT TIC COM INV FIS EMP ETI SST CUL DER | R40: MAT TIC COM FIS SST INV CUL DER ETI EMP | S40: ETI | T40: NELLYS JANETH BLANCO RODRIGUEZ | U40: DER | V40: LIDA ROCIO ROA MONSALVE | W40: MAT | X40: ELKIN DURAN MANCIPE | Y40: TIC | Z40: CRISTINA CASTAÑO CASTILLO | AA40: EMP | AB40: JOHN FRANZ RINCON PENA | AC40: COM | AD40: JORGE ARMANDO PIEDRAHITA CABRERA | AE40: INV | AF40: CINDY YOHANA BOHORQUEZ GARZON | AG40: FIS | AH40: CAMILO ERNESTO CALDERON GALINDO | AK40: SST | AL40: JORGE IVAN PEREZ GAITAN | AW40: CUL | AX40: =IFERROR(VLOOKUP(A40,_p7_2025,2,FALSE),"") -> CHRISTIAN CAMILO RODRIGUEZ SALAS | BV40: Terminó
...

Sheet Hoja3
A1: 1 | B1: 2 | D1: 4 | E1: 5 | F1: 6 | G1: 7 | H1: 8 | I1: 9 | J1: 10 | K1: 11 | L1: 12 | M1: 13 | N1: 14 | P1: 15 | Q1: 16 | R1: 17 | S1: 18 | T1: 19 | U1: 20 | V1: 21 | W1: 22 | X1: 23 | Y1: 24 | Z1: 25 | AA1: 26 | AB1: 27 | AC1: 28 | AD1: 29 | AE1: 30 | AF1: 31 | AG1: 32 | AH1: 33 | AI1: 34 | AJ1: 35 | AK1: 36 | AL1: 37 | AM1: 38 | AN1: 39 | AO1: 40 | AP1: 41 | AQ1: 42 | AR1: 43 | AS1: 44 | AT1: 45 | AU1: 46 | AV1: 47 | AW1: 48 | AX1: 49 | AY1: 50 | AZ1: 51 | BA1: 52 | BB1: 53 | BC1: 54 | BD1: 55 | BK1: 56
A2: FICHA | B2: NIVEL | C2: APRENDICES | D2: PROGRAMA | E2: F_INI | F2: F_FIN_ LEC | G2: F_FIN | H2: INSTRUCTOR_TECNICO 2024 | I2: INSTRUCTOR_TECNICO_ANT 2024 | J2: INSTRUCTOR BIENVENIDA 2024 | K2: INSTRUCTOR INDUCCION 2025 | L2: INSTRUCTOR_TECNICO_ANT 2025 | M2: INSTRUCTOR TECNICO 2025 | N2: INSTRUCTOR_BILINGUISMO 2024/2025 | O2: INSTRUCTOR TECNICO 2026 | P2: INSTRUCTOR BILINGUIMOS 2025 | Q2: TODAS | R2: FALTAN EN 2024 | S2: Transversal 5to periodo | T2: Instructor 5to periodo | U2: Transversal 6to periodo | V2: Instructor 6to periodo | W2: Transversal 7mo periodo | X2: Instructor 7mo periodo | Y2: Transversal 8vo periodo | Z2: Instructor 8vo periodo | AA2: Transversal 9no Periodo | AB2: Instructor 9no periodo | AC2: Transvesal 1er Periodo 2025 | AD2: Instructor 1er Periodo 2025 | AE2: Transversal 2do periodo 2025 | AF2: Instructor 2do periodo 2025 | AG2: Transversal 3er periodo 2025 - A | AH2: Instructor 3er periodo 2025 -A | AI2: Transversal 3er periodo 2025 - B | AJ2: Instructor 3er periodo 2025 - B | AK2: Transvesal 4to periodo 2025 - A | AL2: Instructor 4to periodo 2025 -A | AM2: Transversal 4to periodo 2025 - B | AN2: Instructor 4to periodo 2025 - B | AO2: Transversal 5to periodo 2025 - A | AP2: Instructor 5to periodo 2025 - A | AQ2: Transversal 5to periodo 2025 - B | AR2: Instructor 5to periodo 2025 -B | AS2: Transversal 6to periodo 2025 - A | AT2: Instructor 6to periodo 2025 - A | AU2: Transversal 6to periodo 2025 - B | AV2: Instructor 6to periodo 2025 -B | AW2: Transversal 7mo periodo 2025 - A | AX2: Instructor 7mo periodo 2025 - A | AY2: Transversal 7mo periodo 2025 - B | AZ2: Instructor 7mo periodo 2025 -B | BA2: Transversal 8vo periodo 2025 - A | BB2: Instructor 8vo periodo 2025 - A | BC2: Transversal 8vo periodo 2025 - B | BD2: Instructor 8vo periodo 2025 - B | BE2: Transversal 9vo periodo 2025 - A | BF2: Instructor 9No periodo 2025 - A | BG2: Transversal 9vo periodo 2025 - B | BH2: Instructor 9No periodo 2025 - B | BI2: Transversal 1er periodo 2026 - A | BJ2: Instructor 1er periodo 2026 - A | BK2: FALTAN | BL2: NUEVAS FALTANTES
A3: 3186207 | B3: TECNICO | C3: 71 | D3: OPERACIONES COMERCIALES EN RETAIL | E3: 31/03/2025 | F3: 46021 | G3: 30/06/2026 | K3: KEBIN CUESTA RENTERIA | M3: KEBIN CUESTA RENTERIA | O3: =VLOOKUP(A3,Hoja4!$A$2:$B$247,2,FALSE) -> #N/A | P3: JULIAN FERNANDO GARNICA SEPULVEDA | Q3: FIS SST COM DER ETI EMP CUL MAT TIC | AG3: FIS | AH3: CAMILO ERNESTO CALDERON GALINDO | AI3: COM | AJ3: JORGE ARMANDO PIEDRAHITA | AK3: TIC | AL3: ERICK RUIZ NOREÑA | AM3: MAT | AN3: JULIANA HERNANDEZ BARRERA | AO3: CUL | AP3: MELISSA ANDREA LAITON GARNICA | AS3: ETI | AT3: OLGA STELLA PARDO SARAY | AU3: SST | AV3: JORGE IVAN PEREZ GAITAN | AW3: DER | AX3: =IFERROR(VLOOKUP(A3,_p7_2025,2,FALSE),"") -> HECTOR ANDRES CIPAMOCHA CENTENO | BA3: EMP | BB3: =VLOOKUP(A3,_p8_2025,2,FALSE) -> ESTEFANIA SANDOVAL CRUZ
A4: 3186220 | B4: TECNICO | C4: 90 | D4: OPERACIONES DE COMERCIO EXTERIOR | E4: 31/03/2025 | F4: 46021 | G4: 30/06/2026 | K4: LUISA ADRIANA CORREDOR GALVIS | M4: DARLING NATHALI GOMEZ OSPINA | O4: =VLOOKUP(A4,Hoja4!$A$2:$B$247,2,FALSE) -> #N/A | P4: JULIAN FERNANDO GARNICA SEPULVEDA | Q4: SST COM DER ETI EMP CUL MAT TIC | AG4: SST | AH4: MARINELLA DIAZ ACOSTA | AI4: COM | AJ4: JORGE ARMANDO PIEDRAHITA | AK4: MAT | AL4: WILDER JULIAN ARIAS HERNANDEZ | AM4: TIC | AN4: SONIA PATRICIA CASTAÑEDA CAYCEDO | AO4: CUL | AP4: CHRISTIAN CAMILO RODRIGUEZ SALAS | AS4: ETI | AT4: IVAN DARIO RODRIGUEZ BUSTAMANTE | AW4: EMP | AX4: =IFERROR(VLOOKUP(A4,_p7_2025,2,FALSE),"") -> ESTEFANIA SANDOVAL CRUZ | BA4: DER | BB4: =VLOOKUP(A4,_p8_2025,2,FALSE) -> HECTOR ANDRES CIPAMOCHA CENTENO
A5: 3186221 | B5: TECNICO | C5: 58 | D5: OPERACIONES DE COMERCIO EXTERIOR | E5: 31/03/2025 | F5: 46021 | G5: 30/06/2026 | K5: LUISA ADRIANA CORREDOR GALVIS | M5: DARLING NATHALI GOMEZ OSPINA | O5: =VLOOKUP(A5,Hoja4!$A$2:$B$247,2,FALSE) -> #N/A | P5: JULIAN FERNANDO GARNICA SEPULVEDA | Q5: SST COM DER ETI EMP CUL MAT TIC | AG5: SST | AH5: MARINELLA DIAZ ACOSTA | AI5: COM | AJ5: CESAR AUGUSTO BERMEO | AK5: MAT | AL5: ELKIN DURAN MANCIPE | AM5: TIC | AN5: SONIA PATRICIA CASTAÑEDA CAYCEDO | AO5: CUL | AP5: CHRISTIAN CAMILO RODRIGUEZ SALAS | AS5: ETI | AT5: NELSON ALFREDO VARGAS MORA | AW5: EMP | AX5: =IFERROR(VLOOKUP(A5,_p7_2025,2,FALSE),"") -> ALBERTO ANTONIO TAPIA TORRES | BA5: DER | BB5: =VLOOKUP(A5,_p8_2025,2,FALSE) -> HECTOR ANDRES CIPAMOCHA CENTENO
A6: 3186222 | B6: TECNICO | C6: 64 | D6: OPERACIONES DE COMERCIO EXTERIOR | E6: 31/03/2025 | F6: 46021 | G6: 30/06/2026 | K6: LUISA ADRIANA CORREDOR GALVIS | M6: DARLING NATHALI GOMEZ OSPINA | O6: =VLOOKUP(A6,Hoja4!$A$2:$B$247,2,FALSE) -> #N/A | P6: JULIAN FERNANDO GARNICA SEPULVEDA | Q6: SST COM DER ETI EMP CUL MAT TIC | AG6: SST | AH6: MARINELLA DIAZ ACOSTA | AI6: COM | AJ6: CESAR AUGUSTO BERMEO | AK6: MAT | AL6: ELKIN DURAN MANCIPE | AM6: TIC | AN6: SONIA PATRICIA CASTAÑEDA CAYCEDO | AO6: CUL | AP6: CHRISTIAN CAMILO RODRIGUEZ SALAS | AS6: ETI | AT6: IVAN DARIO RODRIGUEZ BUSTAMANTE | AW6: EMP | AX6: =IFERROR(VLOOKUP(A6,_p7_2025,2,FALSE),"") -> ESTEFANIA SANDOVAL CRUZ | BA6: DER | BB6: =VLOOKUP(A6,_p8_2025,2,FALSE) -> MARIA CAROLINA GOMEZ CALLE
A7: 3186281 | B7: TECNICO | C7: 70 | D7: SERVICIOS COMERCIALES Y FINANCIEROS | E7: 31/03/2025 | F7: 46021 | G7: 30/06/2026 | K7: LAURA CRISTINA RIAÑO ARIZA | M7: LAURA CRISTINA RIAÑO ARIZA | O7: =VLOOKUP(A7,Hoja4!$A$2:$B$247,2,FALSE) -> #N/A | P7: ANGELA JULIETTE SILVA VELANDIA | Q7: TIC MAT COM CUL SST EMP ETI DER | AG7: TIC | AH7: CRISTINA CASTAÑO CASTILLO | AI7: MAT | AJ7: JULIANA HERNANDEZ BARRERA | AK7: ETI | AL7: IVAN DARIO RODRIGUEZ BUSTAMANTE | AM7: CUL | AN7: MELISSA ANDREA LAITON GARNICA | AO7: EMP | AP7: LUIS ARTURO BASTIDAS | AS7: SST | AT7: JORGE IVAN PEREZ GAITAN | AW7: DER | AX7: =IFERROR(VLOOKUP(A7,_p7_2025,2,FALSE),"") -> LAURA STHEPHANIA SANCHEZ PABON | BA7: COM | BB7: =VLOOKUP(A7,_p8_2025,2,FALSE) -> CESAR AUGUSTO BERMEO
A8: 3186282 | B8: TECNICO | C8: 68 | D8: SERVICIOS COMERCIALES Y FINANCIEROS | E8: 31/03/2025 | F8: 46021 | G8: 30/06/2026 | K8: LAURA CRISTINA RIAÑO ARIZA | M8: LAURA CRISTINA RIAÑO ARIZA | O8: =VLOOKUP(A8,Hoja4!$A$2:$B$247,2,FALSE) -> #N/A | P8: ANGELA JULIETTE SILVA VELANDIA | Q8: TIC MAT COM CUL SST EMP ETI DER | AG8: TIC | AH8: CRISTINA CASTAÑO CASTILLO | AI8: MAT | AJ8: JULIANA HERNANDEZ BARRERA | AK8: ETI | AL8: OLGA STELLA PARDO SARAY | AM8: CUL | AN8: MELISSA ANDREA LAITON GARNICA | AO8: EMP | AP8: LUIS ARTURO BASTIDAS | AS8: SST | AT8: DEISY JULIETH GARCIA CASTAÑEDA | AW8: DER | AX8: =IFERROR(VLOOKUP(A8,_p7_2025,2,FALSE),"") -> LAURA STHEPHANIA SANCHEZ PABON | BA8: COM | BB8: =VLOOKUP(A8,_p8_2025,2,FALSE) -> CESAR AUGUSTO BERMEO
